<?xml version="1.0"?>
<robot xmlns:xacro="http://www.ros.org/wiki/xacro" name="robot">
 <link name="base">
	<visual>
		<origin xyz=".47 .39 .99" rpy="0 0 0"/>
		<geometry>
		<box size= ".94 .78 1.98"/>
		</geometry>
   	</visual>
	<collision>
	<origin xyz=".47 .39 .99" rpy="0 0 0"/>
	<geometry>
	<cylinder radius="1" length="0.5"/>
	</geometry>
	</collision>
</link>

<link name="laser_vert_bottom">
	<visual>
		<geometry>
		<box size= ".062 .062 0.087"/>
		</geometry>
	</visual>
	<collision>
	<geometry>
	<cylinder radius="1" length="0.5"/>
	</geometry>	
	</collision>
</link>

<link name="laser_vert_top_right">
	<visual>
		<geometry>
		<box size= ".062 .062 0.087"/>
		</geometry>
	</visual>
	<collision>
	<geometry>
	<cylinder radius="1" length="0.5"/>
	</geometry>
	</collision>
</link>

<link name="laser_vert_top_left">
	<visual>
		<geometry>
		<box size= ".062 .062 0.087"/>
		</geometry>
	</visual>
	<collision>
	<geometry>
	<cylinder radius="1" length="0.5"/>
	</geometry>
	</collision>
</link>

<link name="laser_horiz">
	<visual>
		<geometry>
		<cylinder length=".072" radius=".052"/>
		</geometry>
	</visual>
	<collision>
	<geometry>
	<cylinder radius="1" length="0.5"/>
	</geometry>
	</collision>
</link>

<xacro:macro name="xacro_right" params= "suffix reflect">
<link name="wheel_right">
	<visual>
		<geometry>
		<cylinder length="0.05" radius=".2"/>
		</geometry>
	</visual>
	<collision>
	<geometry>
	<cylinder radius="1" length="0.5"/>
	</geometry>
	</collision>
</link>
</xacro:macro>
<xacro:xacro_right suffix="right" reflect="-1"/>

<xacro:macro name="xacro_left" params= "suffix reflect">
<link name="wheel_left">
	<visual>
		<geometry>
		<cylinder length="0.05" radius=".2"/>
		</geometry>
	</visual>
	<collision>
	<origin xyz="-0.10 0.4 0" rpy="-1.57 0 0"/>
	<geometry>
	<cylinder radius="1" length="0.5"/>
	</geometry>
	</collision>
</link>

</xacro:macro>
<xacro:xacro_left suffix="left" reflect="1"/>
<link name="wheel_center">
	<visual>
		<geometry>
		<cylinder length="0.05" radius=".15"/>
		</geometry>
	</visual>
	<collision>
	<geometry>
	<cylinder radius="1" length="0.5"/>
	</geometry>
	</collision>
</link>

<joint name="base_vert_bottom_joint" type="fixed">
	<origin xyz="0.3158 -0.0021 0.5100" rpy="3.1355 -1.3045 0.0025"/>
	<parent link="base"/>
	<child link="laser_vert_bottom"/>
</joint>

<joint name="base_vert_top_right_joint" type="fixed">
	<origin xyz="0.2978 -0.1450 1.8451" rpy="-1.1760 0.6313 -1.9377"/>
	<parent link="base"/>
	<child link="laser_vert_top_right"/>
</joint>

<joint name="base_vert_top_left_joint" type="fixed">
	<origin xyz="0.2997 0.1531 1.8443" rpy="1.1780 0.6198 1.9560"/>
	<parent link="base"/>
	<child link="laser_vert_top_left"/>
</joint>

<joint name="base_horiz_joint" type="fixed">
	<origin xyz="0.2325 .0001 1.9201" rpy="-0.0012 0.1146 -0.0015"/>
	<parent link="base"/>
	<child link="laser_horiz"/>
</joint>


<xacro:macro name="xacro_name" params= "suffix reflect">
<joint name="base_wheel_right_joint" type="continuous">
	<origin xyz="-0.10 ${reflect * 0.4} 0" rpy="-1.57 0 0"/>
	<parent link="base"/>
	<child link="wheel_right"/>
</joint>
</xacro:macro>
<xacro:xacro_name suffix="right" reflect="-1"/>

<xacro:macro name="xacro_left2" params= "suffix reflect">
<joint name="base_wheel_left_joint" type="continuous">
	<origin xyz="-0.10 0.4 0" rpy="-1.57 0 0"/>
	<parent link="base"/>
	<child link="wheel_left"/>
</joint>
</xacro:macro>
<xacro:xacro_left2 suffix="left" reflect="1"/>

<joint name="base_wheel_center_joint" type="continuous">
	<origin xyz="0.10 0 0" rpy="-1.57 0 0"/>
	<parent link="base"/>
	<child link="wheel_center"/>
</joint>

</robot>
